<?xml version="1.0"?>
<robot name="my_robot" xmlns:xacro="http://www.ros.org/wiki/xacro">
	<include filename="$(find robot)/urdf/my_robot.gazebo" />
	<!--  Footprint -->
	<link name="robot_footprint">
	</link>
	<joint name="robot_footprint_joint" type="fixed">
		<origin xyz="0 0 0" rpy="0 0 0" />
		<parent link="robot_footprint" />
		<child link="chassis" />
	</joint>
	<!-- Chassis -->
	<link name="chassis">
		<pose>
			0 0 0.1 0 0 0
		</pose>
		<inertial>
			<mass value="15.0" />
			<origin xyz="0.0 0 0" rpy=" 0 0 0" />
			<inertia ixx="0.1" ixy="0" ixz="0" iyy="0.1" iyz="0" izz="0.1" />
		</inertial>
		<collision name="collision">
			<origin xyz="0 0 0" rpy=" 0 0 0" />
			<geometry>
				<box size=".8 .5 .1" />
			</geometry>
		</collision>
		<visual name="chassis_visual">
			<origin xyz="0 0 0" rpy=" 0 0 0" />
			<geometry>
				<box size=".8 .5 .1" />
			</geometry>
		</visual>
	</link>
	<gazebo reference="chassis">
		<material>
			Gazebo/Blue
		</material>
	</gazebo>
	<!-- Right Front Wheel -->
	<link name="front_right_wheel">
		<visual>
			<origin xyz="0 0 0" rpy=" 0 1.5707 1.5707" />
			<geometry>
				<cylinder radius="0.1" length="0.05" />
			</geometry>
		</visual>
		<collision>
			<origin xyz="0 0 0" rpy=" 0 1.5707 1.5707" />
			<geometry>
				<cylinder radius="0.1" length="0.05" />
			</geometry>
		</collision>
		<inertial>
			<mass value="5.0" />
			<origin xyz="0 0 0" rpy=" 0 1.5707 1.5707" />
			<inertia ixx="0.1" ixy="0" ixz="0" iyy="0.1" iyz="0" izz="0.1" />
		</inertial>
	</link>
	<joint type="continuous" name="front_right_wheel_hinge">
		<origin xyz="0.2 -0.3 0" rpy="0 0 0" />
		<child link="front_right_wheel" />
		<parent link="chassis" />
		<axis xyz="0 1 0" rpy="0 0 0" />
		<limit effort="10000" velocity="1000" />
		<dynamics damping="1.0" friction="1.0" />
	</joint>
	<gazebo reference="front_right_wheel">
		<material>
			Gazebo/Blue
		</material>
	</gazebo>
	<!-- Left Front Wheel -->
	<link name="front_left_wheel">
		<visual>
			<origin xyz="0 0 0" rpy=" 0 1.5707 1.5707" />
			<geometry>
				<cylinder radius="0.1" length="0.05" />
			</geometry>
		</visual>
		<collision>
			<origin xyz="0 0 0" rpy=" 0 1.5707 1.5707" />
			<geometry>
				<cylinder radius="0.1" length="0.05" />
			</geometry>
		</collision>
		<inertial>
			<mass value="5.0" />
			<origin xyz="0 0 0" rpy=" 0 1.5707 1.5707" />
			<inertia ixx="0.1" ixy="0" ixz="0" iyy="0.1" iyz="0" izz="0.1" />
		</inertial>
	</link>
	<joint type="continuous" name="front_left_wheel_hinge">
		<origin xyz="0.2 0.3 0" rpy="0 0 0" />
		<child link="front_left_wheel" />
		<parent link="chassis" />
		<axis xyz="0 1 0" rpy="0 0 0" />
		<limit effort="10000" velocity="1000" />
		<dynamics damping="1.0" friction="1.0" />
	</joint>
	<gazebo reference="front_left_wheel">
		<material>
			Gazebo/Blue
		</material>
	</gazebo>
	<!-- Back Left Wheel -->
	<link name="back_left_wheel">
		<visual>
			<origin xyz="-0 0 0" rpy=" 0 1.5707 1.5707" />
			<geometry>
				<cylinder radius="0.1" length="0.05" />
			</geometry>
		</visual>
		<collision>
			<origin xyz="-0 0 0" rpy=" 0 1.5707 1.5707" />
			<geometry>
				<cylinder radius="0.1" length="0.05" />
			</geometry>
		</collision>
		<inertial>
			<mass value="5.0" />
			<origin xyz="-0 0 0" rpy=" 0 1.5707 1.5707" />
			<inertia ixx="0.1" ixy="0" ixz="0" iyy="0.1" iyz="0" izz="0.1" />
		</inertial>
	</link>
	<joint type="continuous" name="back_left_wheel_hinge">
		<origin xyz="-0.2 0.3 0" rpy="0 0 0" />
		<child link="back_left_wheel" />
		<parent link="chassis" />
		<axis xyz="0 1 0" rpy="0 0 0" />
		<limit effort="10000" velocity="1000" />
		<dynamics damping="1.0" friction="1.0" />
	</joint>
	<gazebo reference="back_left_wheel">
		<material>
			Gazebo/Blue
		</material>
	</gazebo>
	<!-- Back Right Wheel -->
	<link name="back_right_wheel">
		<visual>
			<origin xyz="-0 0 0" rpy=" 0 1.5707 1.5707" />
			<geometry>
				<cylinder radius="0.1" length="0.05" />
			</geometry>
		</visual>
		<collision>
			<origin xyz="-0 0 0" rpy=" 0 1.5707 1.5707" />
			<geometry>
				<cylinder radius="0.1" length="0.05" />
			</geometry>
		</collision>
		<inertial>
			<mass value="5.0" />
			<origin xyz="-0 0 0" rpy=" 0 1.5707 1.5707" />
			<inertia ixx="0.1" ixy="0" ixz="0" iyy="0.1" iyz="0" izz="0.1" />
		</inertial>
	</link>
	<joint type="continuous" name="back_right_wheel_hinge">
		<origin xyz="-0.2 -0.3 0" rpy="0 0 0" />
		<child link="back_right_wheel" />
		<parent link="chassis" />
		<axis xyz="0 1 0" rpy="0 0 0" />
		<limit effort="10000" velocity="1000" />
		<dynamics damping="1.0" friction="1.0" />
	</joint>
	<gazebo reference="back_right_wheel">
		<material>
			Gazebo/Blue
		</material>
	</gazebo>
	<!-- Camera -->
	<link name="camera">
		<visual>
			<origin xyz="-0.0 0 0" rpy=" 0 0 0" />
			<geometry>
				<box size="0.05 0.05 0.05" />
			</geometry>
		</visual>
		<collision>
			<origin xyz="-0.0 0 0" rpy=" 0 0 0" />
			<geometry>
				<box size="0.05 0.05 0.05" />
			</geometry>
		</collision>
		<inertial>
			<mass value="0.1" />
			<origin xyz="0.0 0 0" rpy=" 0 0 0" />
			<inertia ixx="1e-6" ixy="0" ixz="0" iyy="1e-6" iyz="0" izz="1e-6" />
		</inertial>
	</link>
	<joint type="fixed" name="camera_joint">
		<origin xyz="0.4 0 0" rpy="0 0 0" />
		<child link="camera" />
		<parent link="chassis" />
		<axis xyz="0 1 0" rpy="0 0 0" />
	</joint>
	<gazebo reference="camera">
		<material>
			Gazebo/Red
		</material>
	</gazebo>
	<!-- LIDAR -->
	<link name="hokuyo">
		<visual>
			<origin xyz="-0.0 0 0" rpy=" 0 0 0" />
			<geometry>
				<mesh filename="package://robot/meshes/hokuyo.dae" />
			</geometry>
		</visual>
		<collision>
			<origin xyz="-0.0 0 0" rpy=" 0 0 0" />
			<geometry>
				<box size="0.01 0.01 0.01" />
			</geometry>
		</collision>
		<inertial>
			<mass value="1e-5" />
			<origin xyz="0.0 0 0" rpy=" 0 0 0" />
			<inertia ixx="1e-6" ixy="0" ixz="0" iyy="1e-6" iyz="0" izz="1e-6" />
		</inertial>
	</link>
	<joint type="fixed" name="hokuyo">
		<origin xyz="0.35 0 0.1" rpy="0 0 0" />
		<child link="hokuyo" />
		<parent link="chassis" />
		<axis xyz="0 1 0" rpy="0 0 0" />
	</joint>
</robot>
